<?xml version="1.0"?>
<robot xmlns:xacro="http://www.ros.org/wiki/xacro">
    <xacro:include filename="colors.xacro"/>

    <link name="base_link">
    
    </link>

    <joint name="chassis_joint" type="fixed">
        <parent link="base_link"/>
        <child link="chassis"/>
        <origin xyz="-0.105 0 0"/>
    </joint>

    <link name="chassis">
        <parent link="chassis_joint"/>
        <visual>
            <geometry>
                <box size="0.21 0.135 0.0475"/>
            </geometry>
            <material name="white"/>
        </visual>
        <collision>
            <geometry>
                <box size="0.21 0.135 0.0475"/>
            </geometry>
        </collision>
        <inertial>
            <origin xyz="0 0 0" rpy="0 0 0"/>
            <mass value="0.67"/>
            <inertia 
                ixx="${(1/12) * 0.67 * (0.135*0.135+0.0475*0.0475)}" ixy="0.0" ixz="0.0"
                iyy="${(1/12) * 0.67 * (0.21*0.21+0.0475*0.0475)}" iyz="0.0"
                izz="${(1/12) * 0.67 * (0.21*0.21+0.135*0.135)}"
            />
        </inertial>
    </link>

    <joint name="front_left_wheel_joint" type="continuous">
        <parent link="chassis"/>
        <child link="front_left_wheel"/>
        <origin xyz="-0.08 0.1145 0" rpy="-${pi/2} 0 0"/>
        <axis xyz="0 0 1"/>
    </joint>
0
    <link name="front_left_wheel">
        <visual>
            <geometry>
                <cylinder radius="0.06" length="0.06"/>
            </geometry>
            <material name="blue"/>
        </visual>
        <collision>
            <geometry>
                <cylinder radius="0.06" length="0.06"/>
            </geometry>
        </collision>
        <inertial>
            <origin xyz="0 0 0" rpy="0 0 0"/>
            <mass value="0.17"/>
            <inertia 
                ixx="${(1/12) * 0.17 * (3*0.06*0.06 + 0.06*0.06)}" ixy="0.0" ixz="0.0"
                iyy="${(1/12) * 0.17 * (3*0.06*0.06 + 0.06*0.06)}" iyz="0.0"
                izz="${(1/12) * 0.17 * (0.06*0.06)}"
            />
        </inertial>
    </link>

    <joint name="front_right_wheel_joint" type="continuous">
        <parent link="chassis"/>
        <child link="front_right_wheel"/>
        <origin xyz="-0.08 -0.1145 0" rpy="${pi/2} 0 0"/>
        <axis xyz="0 0 -1"/>
    </joint>

    <link name="front_right_wheel">
        <visual>
            <geometry>
                <cylinder radius="0.06" length="0.06"/>
            </geometry>
            <material name="blue"/>
        </visual>
        <collision>
            <geometry>
                <cylinder radius="0.06" length="0.06"/>
            </geometry>
        </collision>
        <inertial>
            <origin xyz="0 0 0" rpy="0 0 0"/>
            <mass value="0.17"/>
            <inertia 
                ixx="${(1/12) * 0.17 * (3*0.06*0.06 + 0.06*0.06)}" ixy="0.0" ixz="0.0"
                iyy="${(1/12) * 0.17 * (3*0.06*0.06 + 0.06*0.06)}" iyz="0.0"
                izz="${(1/12) * 0.17 * (0.06*0.06)}"
            />
        </inertial>
    </link>


    <joint name="back_left_wheel_joint" type="continuous">
        <parent link="chassis"/>
        <child link="back_left_wheel"/>
        <origin xyz="0.08 0.1145 0" rpy="-${pi/2} 0 0"/>
        <axis xyz="0 0 1"/>
    </joint>
0
    <link name="back_left_wheel">
        <visual>
            <geometry>
                <cylinder radius="0.06" length="0.06"/>
            </geometry>
            <material name="blue"/>
        </visual>
        <collision>
            <geometry>
                <cylinder radius="0.06" length="0.06"/>
            </geometry>
        </collision>
        <inertial>
            <origin xyz="0 0 0" rpy="0 0 0"/>
            <mass value="0.17"/>
            <inertia 
                ixx="${(1/12) * 0.17 * (3*0.06*0.06 + 0.06*0.06)}" ixy="0.0" ixz="0.0"
                iyy="${(1/12) * 0.17 * (3*0.06*0.06 + 0.06*0.06)}" iyz="0.0"
                izz="${(1/12) * 0.17 * (0.06*0.06)}"
            />
        </inertial>
    </link>

    <joint name="back_right_wheel_joint" type="continuous">
        <parent link="chassis"/>
        <child link="back_right_wheel"/>
        <origin xyz="0.08 -0.1145 0" rpy="${pi/2} 0 0"/>
        <axis xyz="0 0 -1"/>
    </joint>

    <link name="back_right_wheel">
        <visual>
            <geometry>
                <cylinder radius="0.06" length="0.06"/>
            </geometry>
            <material name="blue"/>
        </visual>
        <collision>
            <geometry>
                <cylinder radius="0.06" length="0.06"/>
            </geometry>
        </collision>
        <inertial>
            <origin xyz="0 0 0" rpy="0 0 0"/>
            <mass value="0.17"/>
            <inertia 
                ixx="${(1/12) * 0.17 * (3*0.06*0.06 + 0.06*0.06)}" ixy="0.0" ixz="0.0"
                iyy="${(1/12) * 0.17 * (3*0.06*0.06 + 0.06*0.06)}" iyz="0.0"
                izz="${(1/12) * 0.17 * (0.06*0.06)}"
            />
        </inertial>
    </link>


</robot>
